<robot name = "mycar">

    <link name = "base_footprint">
     <visual>
            <geometry>
                <box size="0.001 0.001 0.001" />
            </geometry>
        </visual>
    </link>


    <link name="base_link">
        <visual>
            <geometry>
                <box size="0.5 0.2 0.1" />
            </geometry>
            <origin xyz = "0 0 0" rpy = "0 0 0"/>
            <material name = "car_color">
               <color rgba = "0 0 1.0 1" />
            </material>
        </visual>
    </link>
 
    
    <joint name = "link2base_footprint" type = "fixed" > 
        <parent link = "base_footprint"/>
        <child link = "base_link"/>
        <origin xyz = "0 0 0.05" rpy = "0 0 0 "/>
        <axis xyz = "0 0 0"/>
    </joint>



    <link name="camera">
        <visual>
            <geometry>
                <box size="0.02 0.05 0.05" />
            </geometry>
            <origin xyz="0.0 0 0" rpy="0 0 0" />
            <material name="camera_color">
                <color rgba="0 0 1 1" />
            </material>
        </visual>
    </link>


    <joint name = "camera2base" type = "continuous" > 
        <parent link = "base_link"/>
        <child link = "camera"/>
        <origin xyz = "0.20 0 0.075" rpy = "0 0 0 "/>
        <axis xyz = "0 0 1"/>
    </joint>

  
</robot>