
<robot name = "mycar">
    <!-- 设置机器人底盘并添加摄像头-->
       <link name = "base_footprint">
    <!--添加一个及小的link,再去关联link与base_link的,关节的高度刚好和base_link下沉的高度一致
       就是和半个底盘高度
    -->
       <visual>
            <geometry>
                <box size="0.001 0.001 0.001" />
            </geometry>
        </visual>

    </link>
    <!--底盘link-->
    <link name="base_link">
        <visual>
            <geometry>
                <box size="0.5 0.2 0.1" />
            </geometry>
            <origin xyz = "0 0 0" rpy = "0 0 0"/>
            <material name = "car_color">
               <color rgba = "0 0 1.0 0.5" />
            </material>
        </visual>
    </link>


    
    <!--摄像头link-->
    <link name="camera">
        <visual>
            <geometry>
                <box size="0.02 0.05 0.05" />
            </geometry>

            <origin xyz="0.0 0 0" rpy="0 0 0" />

            <material name="camera_color">
                <color rgba="0 0 1 0.5" />
            </material>
        </visual>
    </link>

    <!--joint   类型-->
    <joint name = "camera2base" type = "continuous" >
        <!--父级link-->
        <parent link = "base_link"/>
        <!--子级link-->
        <child link = "camera"/>
        <!--设置偏移量-->
        <origin xyz = "0.2 0 0.075" rpy = "0 0 0 "/>
        <!--设置关节旋转坐标轴-->
        <axis xyz = "0 0 1"/>
    </joint>

    <!--关联base_footprint与base_link-->
    <joint name = "link2base_footprint" type = "fixed" > 
        <parent link = "base_footprint"/>
        <child link = "base_link"/>
        <!--设置偏移量-->
        <origin xyz = "0 0 0.05" rpy = "0 0 0 "/>
        <!--旋转轴-->
        <axis xyz = "0 0 0"/>
    </joint>
</robot>